<?xml version="1.0"?>
<robot name="ired_robot" xmlns:xacro="http://ros.org/wiki/xacro">
  <xacro:include filename="$(find ired_simulation)/urdf/common_properties.xacro"/>
  <xacro:include filename="$(find ired_simulation)/urdf/ired_robot.gazebo.xacro" />

  <!-- link -->
  <link name="base_footprint"/>
  <link name="imu_link"/>

  <link name="base_link">
    <visual>
      <origin xyz="0.0 0.05 -0.0585" rpy="1.57 0.0 3.14"/>
      <geometry>
        <mesh filename="package://ired_simulation/meshes/Body.stl" scale="0.001 0.001 0.001"/>
      </geometry>
      <material name="light_black"/>
    </visual>
    <collision>
      <origin xyz="0.0 0.0 0.0" rpy="0.0 0.0 0.0"/>
      <geometry>
        <box size="0.25 0.18 0.143"/>
      </geometry>
    </collision>
    <inertial>
      <origin xyz="0 0 0" rpy="0 0 0"/>
      <mass value="8.2573504e-01"/>
      <inertia ixx="2.2124416e-03" ixy="-1.2294101e-05" ixz="3.4938785e-05"
               iyy="2.1193702e-03" iyz="-5.0120904e-06"
               izz="2.0064271e-03" />
    </inertial>
  </link>

  <link name="base_scan">
    <visual>
      <origin xyz="0.09 -0.75 -0.143" rpy="0.0 0.0 0.0"/>
      <geometry>
        <mesh filename="package://ired_simulation/meshes/LiDAR.stl" scale="0.001 0.001 0.001"/>
      </geometry>
      <material name="dark"/>
    </visual>
    <collision>
      <origin xyz="0.015 0 -0.0065" rpy="0 0 0"/>
      <geometry>
        <cylinder length="0.0315" radius="0.055"/>
      </geometry>
    </collision>

    <inertial>
      <mass value="0.114" />
      <origin xyz="0 0 0" />
      <inertia ixx="0.001" ixy="0.0" ixz="0.0"
               iyy="0.001" iyz="0.0"
               izz="0.001" />
    </inertial>
  </link>

  <link name="wheel_left_link">
    <visual>
      <origin xyz="0.0 0.0 0.0" rpy="0.0 -1.57 1.57"/>
      <geometry>
        <mesh filename="package://ired_simulation/meshes/Wheel.stl" scale="0.001 0.001 0.001"/>
      </geometry>
      <material name="black"/>
    </visual>
    <collision>
      <origin xyz="0 0 0" rpy="0 0 0"/>
      <geometry>
        <cylinder length="0.018" radius="0.033"/>
      </geometry>
    </collision>

    <inertial>
      <origin xyz="0 0 0" />
      <mass value="2.8498940e-02" />
      <inertia ixx="1.1175580e-05" ixy="-4.2369783e-11" ixz="-5.9381719e-09"
               iyy="1.1192413e-05" iyz="-1.4400107e-11"
               izz="2.0712558e-05" />
      </inertial>
  </link>

  <link name="wheel_right_link">
    <visual>
      <origin xyz="0.0 0.0 0.0" rpy="0.0 1.57 1.57"/>
      <geometry>
        <mesh filename="package://ired_simulation/meshes/Wheel.stl" scale="0.001 0.001 0.001"/>
      </geometry>
      <material name="black"/>
    </visual>
    <collision>
      <origin xyz="0 0 0" rpy="0 0 0"/>
      <geometry>
        <cylinder length="0.018" radius="0.033"/>
      </geometry>
    </collision>

    <inertial>
      <origin xyz="0 0 0" />
      <mass value="2.8498940e-02" />
      <inertia ixx="1.1175580e-05" ixy="-4.2369783e-11" ixz="-5.9381719e-09"
               iyy="1.1192413e-05" iyz="-1.4400107e-11"
               izz="2.0712558e-05" />
      </inertial>
  </link>

  <link name="caster_front_link">
    <collision>
      <origin xyz="0 0.005 0" rpy="0 0 0"/>
      <geometry>
        <box size="0.033 0.027 0.1"/>
      </geometry>
    </collision>

    <inertial>
      <origin xyz="0 0 0" />
      <mass value="0.005" />
      <inertia ixx="0.001" ixy="0.0" ixz="0.0"
               iyy="0.001" iyz="0.0"
               izz="0.001" />
    </inertial>
  </link>

  <link name="caster_back_link">
    <collision>
      <origin xyz="0 0.005 0" rpy="0 0 0"/>
      <geometry>
        <box size="0.033 0.027 0.1"/>
      </geometry>
    </collision>

    <inertial>
      <origin xyz="0 0 0" />
      <mass value="0.005" />
      <inertia ixx="0.001" ixy="0.0" ixz="0.0"
               iyy="0.001" iyz="0.0"
               izz="0.001" />
    </inertial>
  </link>

  <!-- joint -->
  <joint name="base_joint" type="fixed">
    <parent link="base_footprint"/>
    <child link="base_link"/>
    <origin xyz="0.0 0.0 0.0975" rpy="0.0 0.0 0.0"/>
  </joint>
  <joint name="imu_joint" type="fixed">
    <parent link="base_link"/>
    <child link="imu_link"/>
    <origin xyz="0.0 0.0 0.0" rpy="0.0 0.0 0.0"/>
  </joint>
  <joint name="scan_joint" type="fixed">
    <parent link="base_link"/>
    <child link="base_scan"/>
    <origin xyz="0.0 0.0 0.0963195" rpy="0.0 0.0 0.0"/>
  </joint>
  <joint name="wheel_left_joint" type="continuous">
    <parent link="base_link"/>
    <child link="wheel_left_link"/>
    <axis xyz="0 0 1"/>
    <origin xyz="0.0 0.097 -0.068" rpy="-1.57 0.0 0.0"/>
  </joint>
  <joint name="wheel_right_joint" type="continuous">
    <parent link="base_link"/>
    <child link="wheel_right_link"/>
    <axis xyz="0 0 1"/>
    <origin xyz="0.0 -0.080 -0.068" rpy="-1.57 0.0 0.0"/>
  </joint>
  <joint name="caster_front_joint" type="fixed">
    <parent link="base_link"/>
    <child link="caster_front_link"/>
    <origin xyz="0.11 0 -0.078" rpy="-1.57 0 0"/>
  </joint>
  <joint name="caster_back_joint" type="fixed">
    <parent link="base_link"/>
    <child link="caster_back_link"/>
    <origin xyz="-0.11 0 -0.078" rpy="-1.57 0 0"/>
  </joint>

</robot>